<?xml version="1.0"?>
<robot xmlns:xacro="http://ros.org/wiki/xacro">
  <xacro:macro name="robotiq_hande"  params="prefix">
    <link name="${prefix}robotiq_hande_base_link">
      <inertial>
        <origin xyz="0 0 0.04607" rpy="0 0 0" />
        <mass value="0.86387" />
        <inertia ixx="1017560E-9" ixy="0" ixz="2235E-9" iyy="1028041E-9" iyz="0" izz="489810E-9" />
      </inertial>
      <visual>
        <origin xyz="0 0 0" rpy="0 0 0" />
        <geometry>
          <mesh filename="package://hande_description/meshes/hand-e.dae" scale="0.001 0.001 0.001"/>
        </geometry>
        <material name="Gazebo/Black">
          <color rgba="0.1 0.1 0.1 1" />
        </material>
      </visual>
      <collision>
        <origin xyz="0 0 0" rpy="0 0 0" />
        <geometry>
          <mesh filename="package://hande_description/meshes/hand-e.dae" scale="0.001 0.001 0.001"/>
        </geometry>
      </collision>
    </link>
    <gazebo reference="${prefix}robotiq_hande_base_link">
      <material>Gazebo/Black</material>
      <selfCollide>True</selfCollide>
    </gazebo>

    <link name="${prefix}left_finger">
      <inertial>
        <origin rpy="0 0 0" xyz="0.02262 -0.00759 0.00738"/>
        <mass value="0.03804"/>
        <inertia ixx="13567E-9" ixy="1849E-9" ixz="3622E-9" iyy="15784E-9" iyz="3616E-9" izz="7478E-9"/>
      </inertial>
      <visual>
        <origin rpy="0 0 0" xyz="0 0 0"/>
        <geometry>
          <mesh filename="package://hande_description/meshes/finger_1.dae" scale="0.001 0.001 0.001"/>
        </geometry>
        <material name="Gazebo/Grey">
          <color rgba="0.1 0.1 0.1 1"/>
        </material>
      </visual>
      <collision>
        <origin rpy="0 0 0" xyz="0 0 0"/>
        <geometry>
          <mesh filename="package://hande_description/meshes/finger_1.dae" scale="0.001 0.001 0.001"/>
        </geometry>
      </collision>
    </link>
    <gazebo reference="${prefix}left_finger">
      <material>Gazebo/Grey</material>
      <selfCollide>True</selfCollide>
      <mu1>1000</mu1>
      <mu2>1000</mu2>
      <collision>
      <surface>
        <contact>
          <ode>
            <min_depth>0.001</min_depth>
          </ode>
        </contact>
        <friction>
            <torsional>
              <coefficient>100.0</coefficient>
              <surface_radius>1.0</surface_radius>
              <use_patch_radius>false</use_patch_radius>
            </torsional>
        </friction>
      </surface>
      </collision>
    </gazebo>

    <link name="${prefix}right_finger">
      <inertial>
        <origin rpy="0 0 0" xyz="-0.02262 0.00759 0.00738"/>
        <mass value="0.03804"/>
        <inertia ixx="13567E-9" ixy="1849E-9" ixz="-3622E-9" iyy="15784E-9" iyz="-3616E-9" izz="7478E-9"/>
      </inertial>
      <visual>
        <origin rpy="0 0 0" xyz="0 0 0"/>
        <geometry>
          <mesh filename="package://hande_description/meshes/finger_2.dae" scale="0.001 0.001 0.001"/>
        </geometry>
        <material name="Gazebo/Grey">
          <color rgba="0.1 0.1 0.1 1"/>
        </material>
      </visual>
      <collision>
        <origin rpy="0 0 0" xyz="0 0 0"/>
        <geometry>
          <mesh filename="package://hande_description/meshes/finger_2.dae" scale="0.001 0.001 0.001"/>
        </geometry>
      </collision>
    </link>
    <gazebo reference="${prefix}right_finger">
      <material>Gazebo/Grey</material>
      <selfCollide>True</selfCollide>
      <mu1>1000</mu1>
      <mu2>1000</mu2>
      <collision>
      <surface>
        <contact>
          <ode>
            <min_depth>0.001</min_depth>
          </ode>
        </contact>
        <friction>
            <torsional>
              <coefficient>100.0</coefficient>
              <surface_radius>1.0</surface_radius>
              <use_patch_radius>false</use_patch_radius>
            </torsional>
        </friction>
      </surface>
      </collision>
    </gazebo>

    <joint name="${prefix}left_finger_joint" type="prismatic">
      <origin rpy="0 0 0" xyz="0 0 0.099"/>
      <parent link="${prefix}robotiq_hande_base_link"/>
      <child link="${prefix}left_finger"/>
      <axis xyz="-1 0 0"/>
      <limit effort="130" lower="0" upper="0.024" velocity="0.15"/>
    </joint>
    <gazebo reference="${prefix}left_finger_joint">
      <provideFeedback>True</provideFeedback>
      <implictSpringDamper>True</implictSpringDamper>
    </gazebo>

    <joint name="${prefix}right_finger_joint" type="prismatic">
      <origin rpy="0 0 0" xyz="0 0 0.099"/>
      <parent link="${prefix}robotiq_hande_base_link"/>
      <child link="${prefix}right_finger"/>
      <axis xyz="1 0 0"/>
      <limit effort="130" lower="0" upper="0.024" velocity="0.15"/>
      <!--mimic joint="${prefix}left_finger" multiplier="1" offset="0"/-->
    </joint>
    <gazebo reference="${prefix}right_finger_joint">
      <provideFeedback>True</provideFeedback>
      <implictSpringDamper>True</implictSpringDamper>
    </gazebo>

    <transmission name="${prefix}left_finger_trans">
      <type>transmission_interface/SimpleTransmission</type>
        <joint name="${prefix}left_finger_joint">
          <hardwareInterface>hardware_interface/EffortJointInterface</hardwareInterface>
        </joint>
      <actuator name="${prefix}left_finger_moter">
        <hardwareInterface>hardware_interface/EffortJointInterface</hardwareInterface>
        <mechanicalReduction>1</mechanicalReduction>
      </actuator>
    </transmission>

    <transmission name="${prefix}right_finger_trans">
      <type>transmission_interface/SimpleTransmission</type>
        <joint name="${prefix}right_finger_joint">
          <hardwareInterface>hardware_interface/EffortJointInterface</hardwareInterface>
        </joint>
      <actuator name="${prefix}right_finger_moter">
        <hardwareInterface>hardware_interface/EffortJointInterface</hardwareInterface>
        <mechanicalReduction>1</mechanicalReduction>
      </actuator>
    </transmission>
  </xacro:macro>
</robot>
